[2023-06-12 01:41:58,995] {taskinstance.py:1179} INFO - Dependencies all met for <TaskInstance: tercera_entrega_ecentoz.db_connect scheduled__2023-06-11T00:00:00+00:00 [queued]>
[2023-06-12 01:41:59,006] {taskinstance.py:1179} INFO - Dependencies all met for <TaskInstance: tercera_entrega_ecentoz.db_connect scheduled__2023-06-11T00:00:00+00:00 [queued]>
[2023-06-12 01:41:59,007] {taskinstance.py:1376} INFO - 
--------------------------------------------------------------------------------
[2023-06-12 01:41:59,008] {taskinstance.py:1377} INFO - Starting attempt 1 of 6
[2023-06-12 01:41:59,009] {taskinstance.py:1378} INFO - 
--------------------------------------------------------------------------------
[2023-06-12 01:41:59,025] {taskinstance.py:1397} INFO - Executing <Task(PythonOperator): db_connect> on 2023-06-11 00:00:00+00:00
[2023-06-12 01:41:59,031] {standard_task_runner.py:52} INFO - Started process 235 to run task
[2023-06-12 01:41:59,034] {standard_task_runner.py:79} INFO - Running: ['***', 'tasks', 'run', 'tercera_entrega_ecentoz', 'db_connect', 'scheduled__2023-06-11T00:00:00+00:00', '--job-id', '374', '--raw', '--subdir', 'DAGS_FOLDER/dag_tercera_entrega.py', '--cfg-path', '/tmp/tmpy0htduna', '--error-file', '/tmp/tmpuq3qio4d']
[2023-06-12 01:41:59,036] {standard_task_runner.py:80} INFO - Job 374: Subtask db_connect
[2023-06-12 01:41:59,145] {task_command.py:371} INFO - Running <TaskInstance: tercera_entrega_ecentoz.db_connect scheduled__2023-06-11T00:00:00+00:00 [running]> on host 833a7834a9bc
[2023-06-12 01:41:59,243] {taskinstance.py:1591} INFO - Exporting the following env vars:
AIRFLOW_CTX_DAG_OWNER=ecentoz
AIRFLOW_CTX_DAG_ID=tercera_entrega_ecentoz
AIRFLOW_CTX_TASK_ID=db_connect
AIRFLOW_CTX_EXECUTION_DATE=2023-06-11T00:00:00+00:00
AIRFLOW_CTX_TRY_NUMBER=1
AIRFLOW_CTX_DAG_RUN_ID=scheduled__2023-06-11T00:00:00+00:00
[2023-06-12 01:42:00,815] {taskinstance.py:1909} ERROR - Task failed with exception
Traceback (most recent call last):
  File "/home/airflow/.local/lib/python3.7/site-packages/airflow/operators/python.py", line 171, in execute
    return_value = self.execute_callable()
  File "/home/airflow/.local/lib/python3.7/site-packages/airflow/operators/python.py", line 189, in execute_callable
    return self.python_callable(*self.op_args, **self.op_kwargs)
  File "/opt/airflow/dags/dag_tercera_entrega.py", line 83, in db_connect
    df = data_transform_df()
  File "/opt/airflow/dags/dag_tercera_entrega.py", line 71, in data_transform_df
    df_final = data_from_api()
  File "/opt/airflow/dags/dag_tercera_entrega.py", line 56, in data_from_api
    url = url_base + activo1 + '/' + activo2 + '/history?period_id=30MIN&time_start=' + time_start + '&time_end=' + time_end + '&limit=' + '10000'
TypeError: can only concatenate str (not "datetime.date") to str
[2023-06-12 01:42:00,829] {taskinstance.py:1420} INFO - Marking task as UP_FOR_RETRY. dag_id=tercera_entrega_ecentoz, task_id=db_connect, execution_date=20230611T000000, start_date=20230612T014158, end_date=20230612T014200
[2023-06-12 01:42:00,840] {standard_task_runner.py:97} ERROR - Failed to execute job 374 for task db_connect (can only concatenate str (not "datetime.date") to str; 235)
[2023-06-12 01:42:00,859] {local_task_job.py:156} INFO - Task exited with return code 1
[2023-06-12 01:42:00,885] {local_task_job.py:273} INFO - 0 downstream tasks scheduled from follow-on schedule check
