[2023-06-12 01:58:58,975] {taskinstance.py:1179} INFO - Dependencies all met for <TaskInstance: tercera_entrega_ecentoz.db_connect manual__2023-06-12T01:42:39.079043+00:00 [queued]>
[2023-06-12 01:58:58,991] {taskinstance.py:1179} INFO - Dependencies all met for <TaskInstance: tercera_entrega_ecentoz.db_connect manual__2023-06-12T01:42:39.079043+00:00 [queued]>
[2023-06-12 01:58:58,992] {taskinstance.py:1376} INFO - 
--------------------------------------------------------------------------------
[2023-06-12 01:58:58,992] {taskinstance.py:1377} INFO - Starting attempt 2 of 6
[2023-06-12 01:58:58,993] {taskinstance.py:1378} INFO - 
--------------------------------------------------------------------------------
[2023-06-12 01:58:59,014] {taskinstance.py:1397} INFO - Executing <Task(PythonOperator): db_connect> on 2023-06-12 01:42:39.079043+00:00
[2023-06-12 01:58:59,021] {standard_task_runner.py:52} INFO - Started process 189 to run task
[2023-06-12 01:58:59,024] {standard_task_runner.py:79} INFO - Running: ['***', 'tasks', 'run', 'tercera_entrega_ecentoz', 'db_connect', 'manual__2023-06-12T01:42:39.079043+00:00', '--job-id', '378', '--raw', '--subdir', 'DAGS_FOLDER/dag_tercera_entrega.py', '--cfg-path', '/tmp/tmpa7pgq1a6', '--error-file', '/tmp/tmpy1t95k09']
[2023-06-12 01:58:59,026] {standard_task_runner.py:80} INFO - Job 378: Subtask db_connect
[2023-06-12 01:58:59,118] {task_command.py:371} INFO - Running <TaskInstance: tercera_entrega_ecentoz.db_connect manual__2023-06-12T01:42:39.079043+00:00 [running]> on host 833a7834a9bc
[2023-06-12 01:58:59,243] {taskinstance.py:1591} INFO - Exporting the following env vars:
AIRFLOW_CTX_DAG_OWNER=ecentoz
AIRFLOW_CTX_DAG_ID=tercera_entrega_ecentoz
AIRFLOW_CTX_TASK_ID=db_connect
AIRFLOW_CTX_EXECUTION_DATE=2023-06-12T01:42:39.079043+00:00
AIRFLOW_CTX_TRY_NUMBER=2
AIRFLOW_CTX_DAG_RUN_ID=manual__2023-06-12T01:42:39.079043+00:00
[2023-06-12 01:59:00,912] {taskinstance.py:1909} ERROR - Task failed with exception
Traceback (most recent call last):
  File "/home/airflow/.local/lib/python3.7/site-packages/airflow/operators/python.py", line 171, in execute
    return_value = self.execute_callable()
  File "/home/airflow/.local/lib/python3.7/site-packages/airflow/operators/python.py", line 189, in execute_callable
    return self.python_callable(*self.op_args, **self.op_kwargs)
  File "/opt/airflow/dags/dag_tercera_entrega.py", line 83, in db_connect
    df = data_transform_df()
  File "/opt/airflow/dags/dag_tercera_entrega.py", line 71, in data_transform_df
    df_final = data_from_api()
  File "/opt/airflow/dags/dag_tercera_entrega.py", line 56, in data_from_api
    url = url_base + activo1 + '/' + activo2 + '/history?period_id=30MIN&time_start=' + time_start + '&time_end=' + time_end + '&limit=' + '10000'
TypeError: can only concatenate str (not "datetime.date") to str
[2023-06-12 01:59:00,932] {taskinstance.py:1420} INFO - Marking task as UP_FOR_RETRY. dag_id=tercera_entrega_ecentoz, task_id=db_connect, execution_date=20230612T014239, start_date=20230612T015858, end_date=20230612T015900
[2023-06-12 01:59:00,949] {standard_task_runner.py:97} ERROR - Failed to execute job 378 for task db_connect (can only concatenate str (not "datetime.date") to str; 189)
[2023-06-12 01:59:01,004] {local_task_job.py:156} INFO - Task exited with return code 1
[2023-06-12 01:59:01,147] {local_task_job.py:273} INFO - 0 downstream tasks scheduled from follow-on schedule check
