[2023-06-12 01:17:22,181] {taskinstance.py:1179} INFO - Dependencies all met for <TaskInstance: tercera_entrega_ecentoz.db_connect scheduled__2023-05-31T00:00:00+00:00 [queued]>
[2023-06-12 01:17:22,827] {taskinstance.py:1179} INFO - Dependencies all met for <TaskInstance: tercera_entrega_ecentoz.db_connect scheduled__2023-05-31T00:00:00+00:00 [queued]>
[2023-06-12 01:17:22,838] {taskinstance.py:1376} INFO - 
--------------------------------------------------------------------------------
[2023-06-12 01:17:22,844] {taskinstance.py:1377} INFO - Starting attempt 1 of 6
[2023-06-12 01:17:22,849] {taskinstance.py:1378} INFO - 
--------------------------------------------------------------------------------
[2023-06-12 01:17:23,101] {taskinstance.py:1397} INFO - Executing <Task(PythonOperator): db_connect> on 2023-05-31 00:00:00+00:00
[2023-06-12 01:17:23,403] {standard_task_runner.py:52} INFO - Started process 220 to run task
[2023-06-12 01:17:23,725] {standard_task_runner.py:79} INFO - Running: ['***', 'tasks', 'run', 'tercera_entrega_ecentoz', 'db_connect', 'scheduled__2023-05-31T00:00:00+00:00', '--job-id', '241', '--raw', '--subdir', 'DAGS_FOLDER/dag_tercera_entrega.py', '--cfg-path', '/tmp/tmpuppgs8_w', '--error-file', '/tmp/tmp0sk4x_x6']
[2023-06-12 01:17:23,825] {standard_task_runner.py:80} INFO - Job 241: Subtask db_connect
[2023-06-12 01:17:27,172] {task_command.py:371} INFO - Running <TaskInstance: tercera_entrega_ecentoz.db_connect scheduled__2023-05-31T00:00:00+00:00 [running]> on host f4aa0d8de4f3
[2023-06-12 01:17:28,593] {taskinstance.py:1591} INFO - Exporting the following env vars:
AIRFLOW_CTX_DAG_OWNER=ecentoz
AIRFLOW_CTX_DAG_ID=tercera_entrega_ecentoz
AIRFLOW_CTX_TASK_ID=db_connect
AIRFLOW_CTX_EXECUTION_DATE=2023-05-31T00:00:00+00:00
AIRFLOW_CTX_TRY_NUMBER=1
AIRFLOW_CTX_DAG_RUN_ID=scheduled__2023-05-31T00:00:00+00:00
[2023-06-12 01:17:34,220] {taskinstance.py:1909} ERROR - Task failed with exception
Traceback (most recent call last):
  File "/home/airflow/.local/lib/python3.7/site-packages/airflow/operators/python.py", line 171, in execute
    return_value = self.execute_callable()
  File "/home/airflow/.local/lib/python3.7/site-packages/airflow/operators/python.py", line 189, in execute_callable
    return self.python_callable(*self.op_args, **self.op_kwargs)
  File "/opt/airflow/dags/dag_tercera_entrega.py", line 83, in db_connect
    df = data_transform_df()
  File "/opt/airflow/dags/dag_tercera_entrega.py", line 71, in data_transform_df
    df_final = data_from_api()
  File "/opt/airflow/dags/dag_tercera_entrega.py", line 56, in data_from_api
    url = url_base + activo1 + '/' + activo2 + '/history?period_id=30MIN&time_start=' + time_start + '&time_end=' + time_end + '&limit=' + '10000'
TypeError: can only concatenate str (not "datetime.date") to str
[2023-06-12 01:17:34,319] {taskinstance.py:1420} INFO - Marking task as UP_FOR_RETRY. dag_id=tercera_entrega_ecentoz, task_id=db_connect, execution_date=20230531T000000, start_date=20230612T011722, end_date=20230612T011734
[2023-06-12 01:17:34,363] {standard_task_runner.py:97} ERROR - Failed to execute job 241 for task db_connect (can only concatenate str (not "datetime.date") to str; 220)
[2023-06-12 01:17:34,502] {local_task_job.py:156} INFO - Task exited with return code 1
[2023-06-12 01:17:34,580] {local_task_job.py:273} INFO - 0 downstream tasks scheduled from follow-on schedule check
