[2023-06-12 01:40:59,477] {taskinstance.py:1179} INFO - Dependencies all met for <TaskInstance: tercera_entrega_ecentoz.db_connect scheduled__2023-06-05T00:00:00+00:00 [queued]>
[2023-06-12 01:40:59,528] {taskinstance.py:1179} INFO - Dependencies all met for <TaskInstance: tercera_entrega_ecentoz.db_connect scheduled__2023-06-05T00:00:00+00:00 [queued]>
[2023-06-12 01:40:59,534] {taskinstance.py:1376} INFO - 
--------------------------------------------------------------------------------
[2023-06-12 01:40:59,535] {taskinstance.py:1377} INFO - Starting attempt 5 of 6
[2023-06-12 01:40:59,537] {taskinstance.py:1378} INFO - 
--------------------------------------------------------------------------------
[2023-06-12 01:40:59,598] {taskinstance.py:1397} INFO - Executing <Task(PythonOperator): db_connect> on 2023-06-05 00:00:00+00:00
[2023-06-12 01:40:59,627] {standard_task_runner.py:52} INFO - Started process 214 to run task
[2023-06-12 01:40:59,639] {standard_task_runner.py:79} INFO - Running: ['***', 'tasks', 'run', 'tercera_entrega_ecentoz', 'db_connect', 'scheduled__2023-06-05T00:00:00+00:00', '--job-id', '342', '--raw', '--subdir', 'DAGS_FOLDER/dag_tercera_entrega.py', '--cfg-path', '/tmp/tmpaeojr7bk', '--error-file', '/tmp/tmpcbszu3n0']
[2023-06-12 01:40:59,674] {standard_task_runner.py:80} INFO - Job 342: Subtask db_connect
[2023-06-12 01:40:59,742] {cli_action_loggers.py:105} WARNING - Failed to log action with (psycopg2.OperationalError) connection to server at "postgres" (172.19.0.2), port 5432 failed: server closed the connection unexpectedly
	This probably means the server terminated abnormally
	before or while processing the request.

(Background on this error at: https://sqlalche.me/e/14/e3q8)
[2023-06-12 01:40:59,950] {standard_task_runner.py:97} ERROR - Failed to execute job 342 for task db_connect ((psycopg2.OperationalError) connection to server at "postgres" (172.19.0.2), port 5432 failed: server closed the connection unexpectedly
	This probably means the server terminated abnormally
	before or while processing the request.

(Background on this error at: https://sqlalche.me/e/14/e3q8); 214)
[2023-06-12 01:41:00,023] {local_task_job.py:156} INFO - Task exited with return code 1
