[2023-06-12 01:40:59,497] {taskinstance.py:1179} INFO - Dependencies all met for <TaskInstance: tercera_entrega_ecentoz.db_connect scheduled__2023-06-08T00:00:00+00:00 [queued]>
[2023-06-12 01:40:59,529] {taskinstance.py:1179} INFO - Dependencies all met for <TaskInstance: tercera_entrega_ecentoz.db_connect scheduled__2023-06-08T00:00:00+00:00 [queued]>
[2023-06-12 01:40:59,534] {taskinstance.py:1376} INFO - 
--------------------------------------------------------------------------------
[2023-06-12 01:40:59,535] {taskinstance.py:1377} INFO - Starting attempt 5 of 6
[2023-06-12 01:40:59,537] {taskinstance.py:1378} INFO - 
--------------------------------------------------------------------------------
[2023-06-12 01:40:59,597] {taskinstance.py:1397} INFO - Executing <Task(PythonOperator): db_connect> on 2023-06-08 00:00:00+00:00
[2023-06-12 01:40:59,622] {standard_task_runner.py:52} INFO - Started process 213 to run task
[2023-06-12 01:40:59,677] {standard_task_runner.py:79} INFO - Running: ['***', 'tasks', 'run', 'tercera_entrega_ecentoz', 'db_connect', 'scheduled__2023-06-08T00:00:00+00:00', '--job-id', '349', '--raw', '--subdir', 'DAGS_FOLDER/dag_tercera_entrega.py', '--cfg-path', '/tmp/tmpj5k0z2ur', '--error-file', '/tmp/tmp84pt8hx8']
[2023-06-12 01:40:59,690] {standard_task_runner.py:80} INFO - Job 349: Subtask db_connect
[2023-06-12 01:40:59,734] {cli_action_loggers.py:105} WARNING - Failed to log action with (psycopg2.OperationalError) connection to server at "postgres" (172.19.0.2), port 5432 failed: server closed the connection unexpectedly
	This probably means the server terminated abnormally
	before or while processing the request.

(Background on this error at: https://sqlalche.me/e/14/e3q8)
[2023-06-12 01:40:59,953] {standard_task_runner.py:97} ERROR - Failed to execute job 349 for task db_connect ((psycopg2.OperationalError) connection to server at "postgres" (172.19.0.2), port 5432 failed: server closed the connection unexpectedly
	This probably means the server terminated abnormally
	before or while processing the request.

(Background on this error at: https://sqlalche.me/e/14/e3q8); 213)
[2023-06-12 01:41:00,016] {local_task_job.py:156} INFO - Task exited with return code 1
